Workbook

Sheet Cover
B2: Crego — Client Onboarding Questionnaire
B3: First-call discovery + deep-dive scoping for LOS, LMS, SCF, Term Loan, and LOS-for-SCF/TL
B5: Engagement Snapshot
B6: Client (Legal Name)
B7: Trading / Brand Name
B8: Primary Contact (Name, Role)
B9: Primary Contact Email / Phone
B10: Crego Account Owner
B11: Crego Solutioning Lead
B12: Discovery Call Date
B13: Questionnaire Version | C13: v1.0
B14: Last Updated
B16: How to use this workbook
B17: 1. Start with Sheet 1 — Tier 1 Screener. Run through this with the client on the first discovery call.
B18: 2. Based on which modules are in scope, open the relevant deep-dive sheets (2–6) and fill them as you uncover detail.
B19: 3. Sheets 7–14 are cross-cutting topics (permissions, maker-checker, bulk ops, APIs, compliance, data migration, reporting, timeline). These apply regardless of module.
B20: 4. For every question, set Priority (Must / Should / Nice) and flag Blocker for Go-Live (Yes / No / TBD). Use the dropdowns in columns I and J.
B21: 5. Sheet 15 — Scoping Summary auto-aggregates blocker counts and section completeness to surface risk areas.
B22: 6. Treat the workbook as living. Re-version on each major update; keep prior versions in the release-management folder.
B24: Sheet Index
B25: Sheet | C25: Purpose
B26: 1. Tier 1 — Screener | C26: Cross-product screener for first call. Use this in the discovery meeting; deeper sheets are filled only if relevant.
B27: 2. LOS Deep-Dive | C27: Loan Origination System — retail / unsecured / secured products with consumer-facing journey.
B28: 3. LMS Deep-Dive | C28: Loan Management System — schedules, repayments, servicing, collections, accounting.
B29: 4. SCF Deep-Dive | C29: Supply Chain Finance — anchor / dealer / vendor / factoring / dynamic discounting programs.
B30: 5. Term Loan Deep-Dive | C30: Term loan origination & servicing — sanction structure, drawdown, security, monitoring.
B31: 6. LOS for SCF & TL | C31: Origination workflow specific to SCF & Term Loan — entity KYC, financial analytics, credit memos, committee approvals.
B32: 7. Users, Roles & Access | C32: Role taxonomy, hierarchies, scoped data access, license model.
B33: 8. Maker-Checker & Approvals | C33: Approval matrices, multi-level workflows, audit, escalation.
B34: 9. Bulk Operations | C34: All bulk uploads, approvals, disbursements, postings.
B35: 10. APIs & Integrations | C35: Inbound / outbound APIs, webhooks, vendor integrations inventory.
B36: 11. Compliance & Security | C36: Regulatory frameworks, security controls, privacy, DR/BCP, audit posture.
... B40: 15. Scoping Summary | C40: Auto-aggregated view: question counts, blockers flagged, completeness per section.

Sheet 1. Tier 1 — Screener
A1: 1. Tier 1 — Screener
A2: Cross-product screener for first call. Use this in the discovery meeting; deeper sheets are filled only if relevant.
A4: # | B4: Section | C4: Question | D4: Why it matters / Scoping impact | E4: Response type | F4: Answer | G4: Notes / Follow-up | H4: Owner (Crego) | I4: Priority | J4: Blocker for Go-Live?
A5: Project Basics
A6: 1 | B6: Project Basics | C6: What is your expected go-live date for this product? | D6: Anchors the entire delivery plan and resourcing. | E6: date
A7: 2 | B7: Project Basics | C7: Is there a hard regulatory or business deadline driving this go-live? If yes, describe. | D7: Distinguishes flexible launches from regulator/board commitments. | E7: text
A8: 3 | B8: Project Basics | C8: What is your target UAT start date? | D8: Sets the cutoff for development and integration freeze. | E8: date
A9: 4 | B9: Project Basics | C9: Is this a phased rollout, big-bang, or pilot-first launch? | D9: Determines scope of MVP vs. full release. | E9: single
A10: 5 | B10: Project Basics | C10: Are you using a digital LOS/LMS for the first time, or migrating from an existing system? | D10: Greenfield vs. migration changes effort by 30–50%. | E10: single
A11: 6 | B11: Project Basics | C11: If migrating, which system(s) are you replacing? (vendor + module) | D11: Drives migration scripts and data mapping effort. | E11: text
A12: Modules & Products in Scope
A13: 7 | B13: Modules & Products in Scope | C13: Which Crego modules are in scope for this engagement? (LOS / LMS / SCF / Term Loan / LOS for SCF & TL) | D13: Defines the module set to deploy and configure. | E13: multi
A14: 8 | B14: Modules & Products in Scope | C14: Which loan products will go live in Phase 1? | D14: Each product type adds configuration, document, and rule effort. | E14: text
A15: 9 | B15: Modules & Products in Scope | C15: Are any products planned for later phases? List with target dates. | D15: Helps shape the roadmap beyond Phase 1. | E15: text
A16: 10 | B16: Modules & Products in Scope | C16: What borrower segments do you serve? (retail / SME / corporate / anchor / dealer / vendor) | D16: Drives KYC, underwriting, and journey complexity. | E16: multi
A17: Volume & Scale
A18: 11 | B18: Volume & Scale | C18: Expected applicant/lead volume per month at launch and 12 months out. | D18: Sizes infrastructure, performance SLAs, and bulk handling. | E18: text
A19: 12 | B19: Volume & Scale | C19: Expected monthly disbursement count and ticket size range. | D19: Affects load on disbursement, accounting, and integrations. | E19: text
A20: 13 | B20: Volume & Scale | C20: Live portfolio at go-live (count of active loans + outstanding ₹). | D20: Drives LMS sizing and migration effort. | E20: text
A21: 14 | B21: Volume & Scale | C21: Peak concurrent internal users expected. | D21: Sets license model and performance tests. | E21: number
A22: 15 | B22: Volume & Scale | C22: Geographies / states in scope at launch. | D22: Stamp duty, language, and legal templates vary by state. | E22: text
A23: Users & Channels
A24: 16 | B24: Users & Channels | C24: Internal user count by broad role (sales / credit / ops / risk / collections / admin). | D24: Drives access control and licensing setup. | E24: text
A25: 17 | B25: Users & Channels | C25: Number of external partners (DSAs, branches, anchors, dealers) needing access. | D25: Affects partner onboarding workflow and scaling. | E25: number
A26: 18 | B26: Users & Channels | C26: Customer-facing journey channels needed at launch (web / mobile / assisted / API). | D26: Each channel has its own UI, KYC, and consent flow. | E26: multi
A27: 19 | B27: Users & Channels | C27: Languages required for borrower journey & communications. | D27: Localization adds template + UI work. | E27: text
A28: 20 | B28: Users & Channels | C28: White-label / co-branded UI required? | D28: Theming, domains, and certificates needed. | E28: yesno
A29: Tech Foundations
A30: 21 | B30: Tech Foundations | C30: Hosting preference: Crego SaaS / private cloud / on-prem? | D30: Determines deployment topology and timeline. | E30: single
A31: 22 | B31: Tech Foundations | C31: SSO required? If yes, identity provider (Azure AD / Okta / Keycloak / other). | D31: SSO integration is a non-trivial dependency. | E31: text
A32: 23 | B32: Tech Foundations | C32: Data residency requirements (India / specific region / no preference). | D32: Constrains cloud region and DR strategy. | E32: single
A33: 24 | B33: Tech Foundations | C33: Compliance frameworks the platform must meet (RBI Digital Lending / SOC2 / ISO 27001 / PCI / DPDP). | D33: Each framework has its own controls and evidence. | E33: multi
A34: 25 | B34: Tech Foundations | C34: List the integrations you need at go-live (CBS, bureau, KYC, e-sign, e-mandate, payment gateway, GSTN, AA, etc.). | D34: Each integration is its own mini project. | E34: text
A35: Delivery & Engagement
A36: 26 | B36: Delivery & Engagement | C36: Is there an internal product owner / project manager assigned on your side? | D36: A single accountable owner accelerates delivery. | E36: yesno
A37: 27 | B37: Delivery & Engagement | C37: Do you have BAs, testers, and infra resources available for UAT and integration? | D37: Client-side bandwidth often defines critical path. | E37: yesno
A38: 28 | B38: Delivery & Engagement | C38: Who owns end-user training — Crego or client? | D38: Determines training content and TTT effort. | E38: single
A39: 29 | B39: Delivery & Engagement | C39: Any commercial or budget constraints we should be aware of? | D39: Helps shape MVP and phasing. | E39: text
A40: 30 | B40: Delivery & Engagement | C40: Preferred cadence for status reviews (weekly / bi-weekly / monthly). | D40: Sets governance rhythm. | E40: single

Sheet 2. LOS Deep-Dive
A1: 2. LOS Deep-Dive
A2: Loan Origination System — retail / unsecured / secured products with consumer-facing journey.
A4: # | B4: Section | C4: Question | D4: Why it matters / Scoping impact | E4: Response type | F4: Answer | G4: Notes / Follow-up | H4: Owner (Crego) | I4: Priority | J4: Blocker for Go-Live?
A5: Products & Channels
A6: 1 | B6: Products & Channels | C6: List all retail loan products in scope (e.g., PL, BL, HL, Auto, Gold, Education). | D6: Each product has its own form, eligibility, docs, and scorecards. | E6: text
A7: 2 | B7: Products & Channels | C7: Source channels at launch (DIY web/app / assisted by RM / branch / partner portal / API). | D7: Channel sets determine front-end, auth, and audit needs. | E7: multi
A8: 3 | B8: Products & Channels | C8: Will third-party fintech / aggregator partners originate via API? | D8: Drives outbound API design and onboarding flow. | E8: yesno
A9: 4 | B9: Products & Channels | C9: Pre-approved / pre-qualified offers needed at launch? | D9: Adds offer engine and customer master integration. | E9: yesno
A10: Application Journey
A11: 5 | B11: Application Journey | C11: Walk through your target applicant journey, stage by stage. | D11: Establishes the LOS workflow blueprint. | E11: text
A12: 6 | B12: Application Journey | C12: What data should be prefilled (PAN-driven, mobile-driven, account aggregator, demographic look-up)? | D12: Prefill cuts drop-off but adds integrations. | E12: text
A13: 7 | B13: Application Journey | C13: Are there state-specific or product-specific journey variations? | D13: Branching logic increases configuration time. | E13: yesno
A14: 8 | B14: Application Journey | C14: Is co-applicant / guarantor / joint-applicant support required at launch? | D14: Multi-party flows complicate KYC, agreements, and decisioning. | E14: multi
A15: 9 | B15: Application Journey | C15: Save-and-resume across sessions / channels? | D15: Session state and identity persistence required. | E15: yesno
A16: KYC & Verification
A17: 10 | B17: KYC & Verification | C17: KYC modes required (Aadhaar OKYC / DigiLocker / Video KYC / CKYC / offline). | D17: Each mode requires a different vendor + consent flow. | E17: multi
A18: 11 | B18: KYC & Verification | C18: Identity vendors already empanelled (or to be procured by Crego). | D18: Procurement timelines can block UAT. | E18: text
A19: 12 | B19: KYC & Verification | C19: Penny drop / bank account verification vendor preference. | D19: Common gating step before disbursement. | E19: text
A20: 13 | B20: KYC & Verification | C20: OCR for documents (PAN, Aadhaar, payslip, bank statement) required? | D20: Adds OCR/LLM pipeline and fallback logic. | E20: yesno
A21: 14 | B21: KYC & Verification | C21: Bank statement analysis / GST analytics / ITR analytics needed? | D21: Drives integrations with FinBox / Perfios / FinFort etc. | E21: multi
A22: Underwriting & Decisioning
A23: 15 | B23: Underwriting & Decisioning | C23: Underwriting model: rule engine, score-card, manual, hybrid? | D23: Determines complexity of the decisioning configuration. | E23: single
A24: 16 | B24: Underwriting & Decisioning | C24: Will Crego host the rule engine, or integrate with your existing engine? | D24: Hosting choice affects latency, change management, and audit. | E24: single
A25: 17 | B25: Underwriting & Decisioning | C25: Bureau pulls required (CIBIL / Experian / Equifax / CRIF) and at which stages. | D25: Each bureau is a separate integration with its own contract. | E25: multi
A26: 18 | B26: Underwriting & Decisioning | C26: Hunter / fraud check vendor in scope? | D26: Adds another integration and decisioning step. | E26: yesno
A27: 19 | B27: Underwriting & Decisioning | C27: Decisioning matrix levels (auto-approve / refer / decline / committee). | D27: Determines workflow paths and SLAs. | E27: text
A28: 20 | B28: Underwriting & Decisioning | C28: Are there exception / deviation approval workflows? | D28: Adds maker-checker layers and audit needs. | E28: yesno
A29: Documentation & Sanction
A30: 21 | B30: Documentation & Sanction | C30: Document checklist per product. Static or dynamic by profile? | D30: Dynamic checklists need rule configuration. | E30: single
A31: 22 | B31: Documentation & Sanction | C31: Sanction letter / offer letter templates: count, languages, dynamic fields. | D31: Each template needs design + variable mapping. | E31: text
A32: 23 | B32: Documentation & Sanction | C32: E-sign vendor preference (NSDL / Protean / Leegality / DocuSign). | D32: Affects integration and legal sign-off. | E32: text
A33: 24 | B33: Documentation & Sanction | C33: E-stamping flow needed? Per state stamp duty matrix? | D33: State-specific stamp duty is a large configuration item. | E33: yesno
A34: 25 | B34: Documentation & Sanction | C34: Agreement templates count and variations by product / state. | D34: Each template variant adds review/QA effort. | E34: text
A35: Disbursement
A36: 26 | B36: Disbursement | C36: Disbursement modes (NEFT / RTGS / IMPS / partner / cheque). | D36: Each mode has its own integration and reconciliation. | E36: multi
A37: 27 | B37: Disbursement | C37: Payout via own bank or partner bank? Multiple payout banks? | D37: Multi-bank routing rules add complexity. | E37: single
A38: 28 | B38: Disbursement | C38: Disbursal conditions (post-PDD docs, post-disbursal conditions). | D38: Conditional disbursement extends the workflow. | E38: text
A39: 29 | B39: Disbursement | C39: Tranche disbursement support required at launch? | D39: Common in TL, less in retail; add tranche management. | E39: yesno
A40: Sales Hierarchy & Tracking
A41: 30 | B41: Sales Hierarchy & Tracking | C41: Define your sales hierarchy depth (RM / BM / Cluster / Zonal / National). | D41: Drives access scope and reporting trees. | E41: text
...

Sheet 3. LMS Deep-Dive
A1: 3. LMS Deep-Dive
A2: Loan Management System — schedules, repayments, servicing, collections, accounting.
A4: # | B4: Section | C4: Question | D4: Why it matters / Scoping impact | E4: Response type | F4: Answer | G4: Notes / Follow-up | H4: Owner (Crego) | I4: Priority | J4: Blocker for Go-Live?
A5: Product Master & Schedules
A6: 1 | B6: Product Master & Schedules | C6: Interest computation methods needed (flat / reducing / step-up / step-down / hybrid). | D6: Each method has different schedule logic. | E6: multi
A7: 2 | B7: Product Master & Schedules | C7: Tenure ranges and frequency options (monthly / quarterly / bullet). | D7: Drives schedule generator and dunning. | E7: text
A8: 3 | B8: Product Master & Schedules | C8: Broken period interest / pre-EMI rules. | D8: Edge cases must be agreed before go-live. | E8: text
A9: 4 | B9: Product Master & Schedules | C9: Moratorium support (principal / interest / both). | D9: Common in HL/Edu/MSME loans. | E9: yesno
A10: Repayment & Mandates
A11: 5 | B11: Repayment & Mandates | C11: eNACH / eMandate vendor preference and counter-bank list. | D11: Vendor lead time and mandate registration are critical-path. | E11: text
A12: 6 | B12: Repayment & Mandates | C12: Standing instructions / direct debit alternatives? | D12: Backup repayment methods reduce delinquency. | E12: yesno
A13: 7 | B13: Repayment & Mandates | C13: Auto-presentation calendar and bounce handling rules. | D13: Drives presentation logic and bank charge accounting. | E13: text
A14: 8 | B14: Repayment & Mandates | C14: Multiple repayment instruments per loan (NACH + UPI + cash)? | D14: Hierarchy and reconciliation rules needed. | E14: yesno
A15: Charges, Fees & Penalties
A16: 9 | B16: Charges, Fees & Penalties | C16: Define all charge heads (processing, foreclosure, bounce, late fee, legal, stamp). | D16: Each head has GL mapping and tax treatment. | E16: text
A17: 10 | B17: Charges, Fees & Penalties | C17: Foreclosure / part-payment rules and lock-in periods. | D17: Affects amortization recalculation logic. | E17: text
A18: 11 | B18: Charges, Fees & Penalties | C18: Penalty interest computation method (flat / per day / on overdue). | D18: Compliance with regulator caps must be ensured. | E18: single
A19: 12 | B19: Charges, Fees & Penalties | C19: GST and TDS treatment per charge head. | D19: Tax accounting is non-trivial. | E19: text
A20: Restructure, Top-up & Co-lending
A21: 13 | B21: Restructure, Top-up & Co-lending | C21: Restructure / reschedule support needed at launch? | D21: Adds workflows and audit trails. | E21: yesno
A22: 14 | B22: Restructure, Top-up & Co-lending | C22: Top-up loans on existing accounts? | D22: Customer master + product linkage. | E22: yesno
A23: 15 | B23: Restructure, Top-up & Co-lending | C23: Co-lending / partner sharing of fees, interest, and POS? | D23: Adds split-accounting and partner reporting. | E23: yesno
A24: 16 | B24: Restructure, Top-up & Co-lending | C24: FLDG arrangements with partners? | D24: Compliance per RBI digital lending guidelines. | E24: yesno
A25: Delinquency, Collections & Recovery
A26: 17 | B26: Delinquency, Collections & Recovery | C26: DPD bucketing definition (0/1-30/31-60/...) and NPA classification. | D26: Drives provisioning and reporting. | E26: text
A27: 18 | B27: Delinquency, Collections & Recovery | C27: Collections strategy (in-house, agency, hybrid). Allocation rules? | D27: Drives collections module design. | E27: single
A28: 19 | B28: Delinquency, Collections & Recovery | C28: Field collection mobile app required? | D28: Separate UX with offline support. | E28: yesno
A29: 20 | B29: Delinquency, Collections & Recovery | C29: Recovery / legal handover workflow needed? | D29: Adds case management and document templates. | E29: yesno
A30: 21 | B30: Delinquency, Collections & Recovery | C30: Tele-calling / dialer integration? | D30: Common for early-bucket collections. | E30: yesno
A31: Customer Communication & Self-Service
A32: 22 | B32: Customer Communication & Self-Service | C32: Notification channels (SMS / email / WhatsApp / push) and templates. | D32: Templates need approval per regulator and DLT compliance. | E32: multi
A33: 23 | B33: Customer Communication & Self-Service | C33: Borrower self-service portal / mobile app required? | D33: Adds another front-end. | E33: yesno
A34: 24 | B34: Customer Communication & Self-Service | C34: Self-service features: statement, NoC, foreclosure quote, part-payment, address change. | D34: Each feature is a separate workflow. | E34: multi
A35: 25 | B35: Customer Communication & Self-Service | C35: Grievance / ticketing integration (in-app or external CRM). | D35: RBI mandates grievance redressal SLA. | E35: single
A36: Accounting & Finance
A37: 26 | B37: Accounting & Finance | C37: Accounting / CBS to integrate with (Tally / SAP / Oracle / Finacle / custom). | D37: Integration depth = days to weeks. | E37: text
A38: 27 | B38: Accounting & Finance | C38: GL mapping document available? | D38: Speeds up accounting setup substantially. | E38: yesno
A39: 28 | B39: Accounting & Finance | C39: Day-end / month-end batch dependencies. | D39: Defines batch windows and SLAs. | E39: text
A40: 29 | B40: Accounting & Finance | C40: Insurance integration (single premium, recurring) — partners? | D40: Adds bundled product workflow. | E40: yesno

Sheet 4. SCF Deep-Dive
A1: 4. SCF Deep-Dive
A2: Supply Chain Finance — anchor / dealer / vendor / factoring / dynamic discounting programs.
A4: # | B4: Section | C4: Question | D4: Why it matters / Scoping impact | E4: Response type | F4: Answer | G4: Notes / Follow-up | H4: Owner (Crego) | I4: Priority | J4: Blocker for Go-Live?
A5: Program Design
A6: 1 | B6: Program Design | C6: SCF programs in scope (dealer financing / vendor financing / factoring / reverse factoring / dynamic discounting). | D6: Each program is a distinct workflow. | E6: multi
A7: 2 | B7: Program Design | C7: Anchor model: single anchor / multi-anchor / anchor-less. | D7: Drives onboarding hierarchy. | E7: single
A8: 3 | B8: Program Design | C8: Recourse, non-recourse, or partial-recourse? | D8: Affects credit policy and accounting. | E8: single
A9: 4 | B9: Program Design | C9: Pricing structure: anchor-level, counterparty-level, or both? | D9: Configuration of pricing matrices. | E9: single
A10: Anchor & Counterparty Onboarding
A11: 5 | B11: Anchor & Counterparty Onboarding | C11: Anchor onboarding flow steps and approval levels. | D11: Drives anchor master and limit setup. | E11: text
A12: 6 | B12: Anchor & Counterparty Onboarding | C12: Counterparty (dealer/vendor) onboarding — bulk supported? | D12: High-volume onboarding needs bulk + auto-KYC. | E12: yesno
A13: 7 | B13: Anchor & Counterparty Onboarding | C13: Limit setup: only anchor level, only counterparty level, or hierarchical? | D13: Limit hierarchy is core to SCF. | E13: single
A14: 8 | B14: Anchor & Counterparty Onboarding | C14: KYC requirements for entities (PAN, GST, MOA/AOA, Board Resolution, beneficial owners). | D14: Entity KYC is heavier than retail KYC. | E14: text
A15: Invoice & Transaction Flow
A16: 9 | B16: Invoice & Transaction Flow | C16: Invoice ingestion modes (manual upload / API / EDI / portal scrape / e-Invoice GSTN). | D16: Each mode is a separate ingestion pipeline. | E16: multi
A17: 10 | B17: Invoice & Transaction Flow | C17: Validation rules (3-way match, GST verification, duplicate detection). | D17: Drives validation engine. | E17: text
A18: 11 | B18: Invoice & Transaction Flow | C18: Disbursement triggers (anchor approval / deemed acceptance T+n / counterparty request). | D18: Determines workflow timer logic. | E18: single
A19: 12 | B19: Invoice & Transaction Flow | C19: Tenure & rollover rules per program. | D19: Affects schedule generator and limit recycling. | E19: text
A20: 13 | B20: Invoice & Transaction Flow | C20: Dynamic discounting tiers and slab logic? | D20: Adds pricing engine work. | E20: yesno
A21: Repayment & Reconciliation
A22: 14 | B22: Repayment & Reconciliation | C22: Repayment source (anchor sweep / counterparty direct / NACH / virtual account). | D22: Each path has its own reconciliation logic. | E22: multi
A23: 15 | B23: Repayment & Reconciliation | C23: Virtual account setup with which sponsor bank? | D23: Bank dependency for VA provisioning. | E23: text
A24: 16 | B24: Repayment & Reconciliation | C24: Settlement frequency to anchor (T+0, T+1, weekly). | D24: Drives settlement engine SLA. | E24: single
A25: 17 | B25: Repayment & Reconciliation | C25: Reconciliation reports needed by anchor, counterparty, and lender. | D25: Each stakeholder gets distinct view. | E25: text
A26: Reporting & Integration
A27: 18 | B27: Reporting & Integration | C27: Anchor portal / dealer portal needed at launch? | D27: Separate UI per persona. | E27: multi
A28: 19 | B28: Reporting & Integration | C28: Reporting to GSTN / e-Invoice obligations? | D28: Compliance integration. | E28: yesno
A29: 20 | B29: Reporting & Integration | C29: Integration with anchor's ERP (SAP / Oracle / Tally / custom)? | D29: Common requirement; ERP sandbox needed. | E29: yesno

Sheet 5. Term Loan Deep-Dive
A1: 5. Term Loan Deep-Dive
A2: Term loan origination & servicing — sanction structure, drawdown, security, monitoring.
A4: # | B4: Section | C4: Question | D4: Why it matters / Scoping impact | E4: Response type | F4: Answer | G4: Notes / Follow-up | H4: Owner (Crego) | I4: Priority | J4: Blocker for Go-Live?
A5: Sanction & Drawdown
A6: 1 | B6: Sanction & Drawdown | C6: Sanction structure (single sanction, multi-tranche, revolving). | D6: Affects sanction limit + drawdown logic. | E6: single
A7: 2 | B7: Sanction & Drawdown | C7: Drawdown rules and conditions precedent (CP) checklist. | D7: Each CP is a workflow gate. | E7: text
A8: 3 | B8: Sanction & Drawdown | C8: Milestone / project monitoring required for drawdown release? | D8: Adds inspection and certificate workflows. | E8: yesno
A9: 4 | B9: Sanction & Drawdown | C9: Moratorium support (principal-only / interest-only / both)? | D9: Common in TL; affects schedule. | E9: single
A10: Pricing & Schedules
A11: 5 | B11: Pricing & Schedules | C11: Floating vs. fixed rate, with reset frequency and benchmark (Repo / MCLR / EBLR). | D11: Drives rate reset engine. | E11: text
A12: 6 | B12: Pricing & Schedules | C12: Pre-EMI vs. full EMI period rules. | D12: Affects schedule transitions. | E12: text
A13: 7 | B13: Pricing & Schedules | C13: Pre-payment / part-payment lock-in and rules. | D13: Compliance with RBI cap on charges. | E13: text
A14: Security & Charge Management
A15: 8 | B15: Security & Charge Management | C15: Security types in scope (mortgage / hypothecation / pledge / personal guarantee). | D15: Each has its own document set. | E15: multi
A16: 9 | B16: Security & Charge Management | C16: CERSAI / ROC / sub-registrar charge filing required? | D16: Adds external filing workflow. | E16: multi
A17: 10 | B17: Security & Charge Management | C17: Stamp duty handling: per-state matrix maintained? | D17: Often a separate config exercise. | E17: yesno
A18: 11 | B18: Security & Charge Management | C18: Insurance & valuation requirements (frequency, vendor)? | D18: Periodic monitoring obligations. | E18: text
A19: Covenant & Periodic Monitoring
A20: 12 | B20: Covenant & Periodic Monitoring | C20: Financial covenant monitoring (DSCR, leverage, interest cover) required? | D20: Periodic checks need data + alerts. | E20: yesno
A21: 13 | B21: Covenant & Periodic Monitoring | C21: Frequency of stock / debtor statements required? | D21: Adds periodic data collection workflow. | E21: single
A22: 14 | B22: Covenant & Periodic Monitoring | C22: Renewal / annual review cycle automation needed? | D22: Adds review workflow + reminders. | E22: yesno

Sheet 6. LOS for SCF & TL
A1: 6. LOS for SCF & TL
A2: Origination workflow specific to SCF & Term Loan — entity KYC, financial analytics, credit memos, committee approvals.
A4: # | B4: Section | C4: Question | D4: Why it matters / Scoping impact | E4: Response type | F4: Answer | G4: Notes / Follow-up | H4: Owner (Crego) | I4: Priority | J4: Blocker for Go-Live?
A5: Entity Origination Specifics
A6: 1 | B6: Entity Origination Specifics | C6: Entity types served (Pvt Ltd / LLP / Partnership / Sole Prop / Trust / HUF / Society). | D6: Each entity type changes KYC and document set. | E6: multi
A7: 2 | B7: Entity Origination Specifics | C7: Group / related party assessment workflow needed? | D7: Common for SME/Corporate; affects credit memo. | E7: yesno
A8: 3 | B8: Entity Origination Specifics | C8: Beneficial ownership / UBO declaration capture? | D8: RBI / FATCA / CRS implications. | E8: yesno
A9: Financial & Credit Analytics
A10: 4 | B10: Financial & Credit Analytics | C10: Financial statement analysis (last N years audited financials)? | D10: Adds spread-sheet / OCR pipeline. | E10: yesno
A11: 5 | B11: Financial & Credit Analytics | C11: CMA data ingestion required? | D11: Common for working capital and TL. | E11: yesno
A12: 6 | B12: Financial & Credit Analytics | C12: Banking analytics / GST analytics integration vendor? | D12: Vendor-led integration. | E12: text
A13: 7 | B13: Financial & Credit Analytics | C13: DSCR / cash-flow projection computation in tool? | D13: Calc engine vs. manual upload. | E13: single
A14: Credit Decisioning & Approval
A15: 8 | B15: Credit Decisioning & Approval | C15: Credit memo template + variables. | D15: Each variable maps to data points to capture. | E15: text
A16: 9 | B16: Credit Decisioning & Approval | C16: Committee approval workflow (RM → Credit → Sanctioning Committee → Board)? | D16: Multi-step approval engine + delegation. | E16: yesno
A17: 10 | B17: Credit Decisioning & Approval | C17: Voting / quorum rules for committee? | D17: Influences workflow design. | E17: text
A18: 11 | B18: Credit Decisioning & Approval | C18: Deviation / waiver tracking required? | D18: Audit and reporting need. | E18: yesno
A19: Documentation
A20: 12 | B20: Documentation | C20: Sanction letter / facility agreement templates count and variants. | D20: Each variant needs review. | E20: text
A21: 13 | B21: Documentation | C21: Personal guarantee / corporate guarantee documents in scope? | D21: Adds to document workflow. | E21: multi
A22: 14 | B22: Documentation | C22: Standard term sheet generation? | D22: Pre-sanction commitment workflow. | E22: yesno

Sheet 7. Users, Roles & Access
A1: 7. Users, Roles & Access
A2: Role taxonomy, hierarchies, scoped data access, license model.
A4: # | B4: Section | C4: Question | D4: Why it matters / Scoping impact | E4: Response type | F4: Answer | G4: Notes / Follow-up | H4: Owner (Crego) | I4: Priority | J4: Blocker for Go-Live?
A5: Roles & Hierarchy
A6: 1 | B6: Roles & Hierarchy | C6: Provide role taxonomy (role name, description) and approximate user count per role. | D6: Foundation for RBAC configuration. | E6: text
A7: 2 | B7: Roles & Hierarchy | C7: Org hierarchy depth (e.g., RM → BM → Cluster → Zonal → National). | D7: Drives data scoping. | E7: text
A8: 3 | B8: Roles & Hierarchy | C8: Branch / region / state granularity for access scoping. | D8: Geo scope must be modelled in role design. | E8: text
A9: 4 | B9: Roles & Hierarchy | C9: Concurrent active user count expected at peak. | D9: Sets license model and infra sizing. | E9: number
A10: 5 | B10: Roles & Hierarchy | C10: Named-user vs. concurrent-user license model preference? | D10: Commercial implication. | E10: single
A11: Permissions & Data Access
A12: 6 | B12: Permissions & Data Access | C12: Field-level permissions needed (e.g., mask PAN, hide disbursed amount)? | D12: Adds field-level visibility config. | E12: yesno
A13: 7 | B13: Permissions & Data Access | C13: Data scope per role (own / team / branch / region / all). | D13: Drives row-level security. | E13: text
A14: 8 | B14: Permissions & Data Access | C14: Time-bound or temporary access (audit, contract user)? | D14: Adds expiry & approval workflow. | E14: yesno
A15: 9 | B15: Permissions & Data Access | C15: Out-of-office delegation needed? | D15: Common in approval workflows. | E15: yesno
A16: 10 | B16: Permissions & Data Access | C16: Self-service password reset / unlock? | D16: Reduces helpdesk load. | E16: yesno
A17: External Users
A18: 11 | B18: External Users | C18: Partner / DSA portal users — count and roles. | D18: Separate auth + data isolation. | E18: text
A19: 12 | B19: External Users | C19: Customer-facing logins required at launch? | D19: Self-service portal scope. | E19: yesno
A20: 13 | B20: External Users | C20: Service / API integration users (system accounts)? | D20: Token rotation, scopes, audit. | E20: yesno

Sheet 8. Maker-Checker & Approvals
A1: 8. Maker-Checker & Approvals
A2: Approval matrices, multi-level workflows, audit, escalation.
A4: # | B4: Section | C4: Question | D4: Why it matters / Scoping impact | E4: Response type | F4: Answer | G4: Notes / Follow-up | H4: Owner (Crego) | I4: Priority | J4: Blocker for Go-Live?
A5: Maker-Checker Coverage
A6: 1 | B6: Maker-Checker Coverage | C6: List actions that must go through maker-checker (loan creation / disbursement / fee waiver / etc.). | D6: Determines which workflows have approval queues. | E6: text
A7: 2 | B7: Maker-Checker Coverage | C7: Number of approval levels per action type (1 / 2 / 3 / variable by amount). | D7: Drives matrix complexity. | E7: text
A8: 3 | B8: Maker-Checker Coverage | C8: Approval matrix dimensions (amount, product, branch, risk grade). | D8: Multi-dimensional matrices add config time. | E8: multi
A9: 4 | B9: Maker-Checker Coverage | C9: Auto-approve thresholds (e.g., < ₹X auto-approves)? | D9: Adds rule engine integration. | E9: yesno
A10: SLA, Escalation & Audit
A11: 5 | B11: SLA, Escalation & Audit | C11: SLA per approval level + auto-escalation behaviour? | D11: Notification + reassignment logic. | E11: text
A12: 6 | B12: SLA, Escalation & Audit | C12: Out-of-office / delegation mechanism? | D12: Required for continuity. | E12: yesno
A13: 7 | B13: SLA, Escalation & Audit | C13: Audit trail granularity (before/after value, actor, IP, timestamp). | D13: Compliance / forensic requirement. | E13: text
A14: 8 | B14: SLA, Escalation & Audit | C14: Bulk actions also under maker-checker? | D14: Often missed; needs explicit decision. | E14: yesno
A15: 9 | B15: SLA, Escalation & Audit | C15: Reason codes / comments mandatory at approval / rejection? | D15: Adds dropdown master + validation. | E15: yesno

Sheet 9. Bulk Operations
A1: 9. Bulk Operations
A2: All bulk uploads, approvals, disbursements, postings.
A4: # | B4: Section | C4: Question | D4: Why it matters / Scoping impact | E4: Response type | F4: Answer | G4: Notes / Follow-up | H4: Owner (Crego) | I4: Priority | J4: Blocker for Go-Live?
A5: Bulk Use Cases
A6: 1 | B6: Bulk Use Cases | C6: Bulk upload of leads / applicants? | D6: Defines lead-import job. | E6: yesno
A7: 2 | B7: Bulk Use Cases | C7: Bulk upload of customers / dealers / anchors (SCF)? | D7: Counterparty bulk onboarding. | E7: yesno
A8: 3 | B8: Bulk Use Cases | C8: Bulk approval / rejection of applications? | D8: Common for high-volume retail. | E8: yesno
A9: 4 | B9: Bulk Use Cases | C9: Bulk disbursement file processing? | D9: Treasury / payout integration. | E9: yesno
A10: 5 | B10: Bulk Use Cases | C10: Bulk repayment posting (collections file)? | D10: End-of-day posting flow. | E10: yesno
A11: 6 | B11: Bulk Use Cases | C11: Bulk limit setup / revision (SCF)? | D11: Anchor-driven limit refresh. | E11: yesno
A12: 7 | B12: Bulk Use Cases | C12: Bulk document upload (DMS bulk push)? | D12: DMS integration sizing. | E12: yesno
A13: 8 | B13: Bulk Use Cases | C13: Bulk waiver / fee adjustment? | D13: Frequent in collections. | E13: yesno
A14: Volumes & Format
A15: 9 | B15: Volumes & Format | C15: Largest expected file size (rows / MB) per bulk operation. | D15: Drives async vs. sync design. | E15: text
A16: 10 | B16: Volumes & Format | C16: Acceptable file formats (CSV / XLSX / JSON / fixed-width). | D16: Affects parser and validation. | E16: multi
A17: 11 | B17: Volumes & Format | C17: Frequency of bulk ops (real-time / hourly / daily / EOD / ad-hoc). | D17: Drives batch scheduler design. | E17: text
A18: 12 | B18: Volumes & Format | C18: Maker-checker on bulk uploads? | D18: Adds approval step before commit. | E18: yesno
A19: 13 | B19: Volumes & Format | C19: Error file format & re-upload mechanism required? | D19: Improves operability. | E19: yesno

Sheet 10. APIs & Integrations
A1: 10. APIs & Integrations
A2: Inbound / outbound APIs, webhooks, vendor integrations inventory.
A4: # | B4: Section | C4: Question | D4: Why it matters / Scoping impact | E4: Response type | F4: Answer | G4: Notes / Follow-up | H4: Owner (Crego) | I4: Priority | J4: Blocker for Go-Live?
A5: API Strategy
A6: 1 | B6: API Strategy | C6: List inbound APIs Crego must expose (with consumers). | D6: API contract definition is critical-path. | E6: text
A7: 2 | B7: API Strategy | C7: List outbound APIs Crego must consume (vendor + purpose). | D7: Vendor sandbox availability is a risk. | E7: text
A8: 3 | B8: API Strategy | C8: Auth mechanism preference (OAuth2 / API key / mTLS / JWT). | D8: Affects gateway and onboarding. | E8: single
A9: 4 | B9: API Strategy | C9: Rate limits / throughput SLAs per consumer. | D9: Capacity planning input. | E9: text
A10: 5 | B10: API Strategy | C10: Webhook events Crego must emit (list). | D10: Drives event design + retry/DLQ. | E10: text
A11: Integrations Inventory
A12: 6 | B12: Integrations Inventory | C12: Bureau (CIBIL / Experian / Equifax / CRIF) — which, who holds the contract? | D12: Each bureau has its own implementation effort. | E12: text
A13: 7 | B13: Integrations Inventory | C13: KYC vendors (Karza / Signzy / IDfy / HyperVerge / NSDL / other)? | D13: Vendor lead time often gates UAT. | E13: text
A14: 8 | B14: Integrations Inventory | C14: E-sign vendor (Leegality / Protean / DocuSign / Adobe)? | D14: Affects legal & journey. | E14: single
A15: 9 | B15: Integrations Inventory | C15: E-mandate / NACH (NPCI Net / vendor TSP)? | D15: Mandate provisioning takes weeks. | E15: text
A16: 10 | B16: Integrations Inventory | C16: Payment gateway / payout (Razorpay / Cashfree / partner bank)? | D16: Affects disbursement & repayment. | E16: text
A17: 11 | B17: Integrations Inventory | C17: Account Aggregator integration & TSP/FIU registration status. | D17: AA workflow has its own consent path. | E17: text
A18: 12 | B18: Integrations Inventory | C18: Video KYC vendor (in-house / partner)? | D18: Required for certain RBI use cases. | E18: text
A19: 13 | B19: Integrations Inventory | C19: Fraud / Hunter (NHFIN / Experian Hunter / other)? | D19: Adds underwriting integration. | E19: text
A20: 14 | B20: Integrations Inventory | C20: CBS / core banking integration (which CBS, what scope)? | D20: High effort; varies wildly by CBS. | E20: text
A21: 15 | B21: Integrations Inventory | C21: DMS / document storage (in-house / Newgen / OmniDocs / other)? | D21: Affects document-write path. | E21: text
A22: 16 | B22: Integrations Inventory | C22: Communication (SMS / WhatsApp / Email / IVR vendors)? | D22: DLT / template approvals add lead time. | E22: multi
A23: 17 | B23: Integrations Inventory | C23: BI / data warehouse / analytics (Power BI / Tableau / Metabase / Snowflake / Redshift / other)? | D23: Scopes ETL + access pattern. | E23: text
A24: 18 | B24: Integrations Inventory | C24: Ticketing / CRM (Freshdesk / Zoho / Salesforce / other)? | D24: Grievance + ops integration. | E24: text

Sheet 11. Compliance & Security
A1: 11. Compliance & Security
A2: Regulatory frameworks, security controls, privacy, DR/BCP, audit posture.
A4: # | B4: Section | C4: Question | D4: Why it matters / Scoping impact | E4: Response type | F4: Answer | G4: Notes / Follow-up | H4: Owner (Crego) | I4: Priority | J4: Blocker for Go-Live?
A5: Regulatory & Frameworks
A6: 1 | B6: Regulatory & Frameworks | C6: Primary regulator(s) — RBI / SEBI / IRDAI / international? | D6: Determines applicable controls. | E6: multi
A7: 2 | B7: Regulatory & Frameworks | C7: Entity type (NBFC / Bank / Co-op / HFC / Fintech LSP / other) + license details. | D7: Drives prudential reporting and audit requirements. | E7: text
A8: 3 | B8: Regulatory & Frameworks | C8: RBI Digital Lending Guidelines applicability and any exemptions? | D8: Critical compliance gate. | E8: text
A9: 4 | B9: Regulatory & Frameworks | C9: DPDP / GDPR applicability? | D9: Privacy controls and DSR workflows. | E9: yesno
A10: 5 | B10: Regulatory & Frameworks | C10: PCI DSS scope (storing / processing card data)? | D10: Determines PCI environment scope. | E10: yesno
A11: 6 | B11: Regulatory & Frameworks | C11: ISO 27001 / SOC 2 evidence required at go-live? | D11: Adds artefact + control evidence work. | E11: multi
A12: Security Controls
A13: 7 | B13: Security Controls | C13: Encryption at rest / in transit standards & KMS preference. | D13: Customer-managed vs. provider-managed keys. | E13: text
A14: 8 | B14: Security Controls | C14: Data residency requirements (India / region / specific country). | D14: Constrains hosting region. | E14: single
A15: 9 | B15: Security Controls | C15: Single-tenant vs. multi-tenant deployment requirement? | D15: Big architectural decision. | E15: single
A16: 10 | B16: Security Controls | C16: VAPT cadence and last-test report availability? | D16: Sets pre-go-live security pass. | E16: text
A17: 11 | B17: Security Controls | C17: Audit logging retention period. | D17: Storage & WORM requirements. | E17: text
A18: 12 | B18: Security Controls | C18: DR strategy — RTO / RPO targets. | D18: Drives DR design and rehearsal. | E18: text
A19: 13 | B19: Security Controls | C19: Backup retention and restore test cadence. | D19: Compliance + operational requirement. | E19: text
A20: 14 | B20: Security Controls | C20: Whistleblower / Sachet / Ombudsman integration? | D20: RBI directive compliance. | E20: yesno
A21: Privacy & Consent
A22: 15 | B22: Privacy & Consent | C22: Consent capture for each downstream sharing (bureau, AA, KYC vendor)? | D22: Required by DPDP and RBI DLG. | E22: yesno
A23: 16 | B23: Privacy & Consent | C23: Right-to-erasure / data subject request workflow? | D23: DPDP requirement. | E23: yesno
A24: 17 | B24: Privacy & Consent | C24: Cookie / privacy notice published on customer journey? | D24: Standard but easy to miss. | E24: yesno

Sheet 12. Data Migration
A1: 12. Data Migration
A2: Source inventory, cutover strategy, reconciliation, document & history migration.
A4: # | B4: Section | C4: Question | D4: Why it matters / Scoping impact | E4: Response type | F4: Answer | G4: Notes / Follow-up | H4: Owner (Crego) | I4: Priority | J4: Blocker for Go-Live?
A5: Source Inventory
A6: 1 | B6: Source Inventory | C6: List source systems and modules to migrate from. | D6: Each source has unique extract effort. | E6: text
A7: 2 | B7: Source Inventory | C7: Available export formats (DB dump / API / files). | D7: Drives ETL approach. | E7: multi
A8: 3 | B8: Source Inventory | C8: Volume by entity (leads / customers / loans active / closed / documents). | D8: Sizes migration effort. | E8: text
A9: Strategy
A10: 4 | B10: Strategy | C10: Cutover strategy (parallel run / phased / big-bang). | D10: Defines risk profile. | E10: single
A11: 5 | B11: Strategy | C11: Reconciliation approach and acceptance criteria for cut-over? | D11: Critical for sign-off. | E11: text
A12: 6 | B12: Strategy | C12: Number of mock-migration cycles planned? | D12: Quality of migration depends on iterations. | E12: number
A13: 7 | B13: Strategy | C13: Document migration scope (active loans only / full archive)? | D13: DMS storage and indexing. | E13: single
A14: 8 | B14: Strategy | C14: Customer master deduplication required? | D14: PII matching adds effort. | E14: yesno
A15: 9 | B15: Strategy | C15: Open ticket / case migration? | D15: Continuity of customer service. | E15: yesno
A16: 10 | B16: Strategy | C16: Historical reporting in new system or kept in legacy (read-only)? | D16: Often the cheapest path is dual-system. | E16: single

Sheet 13. Reporting & Dashboards
A1: 13. Reporting & Dashboards
A2: MIS, regulatory reports, dashboards, BI integration.
A4: # | B4: Section | C4: Question | D4: Why it matters / Scoping impact | E4: Response type | F4: Answer | G4: Notes / Follow-up | H4: Owner (Crego) | I4: Priority | J4: Blocker for Go-Live?
A5: Standard MIS
A6: 1 | B6: Standard MIS | C6: List standard MIS reports needed at go-live with frequency. | D6: Each report has design + data work. | E6: text
A7: 2 | B7: Standard MIS | C7: Regulatory reports (CRILC / CIC / PSL / FLDG / NHB / other) in scope? | D7: Each has fixed format and submission path. | E7: multi
A8: 3 | B8: Standard MIS | C8: Statutory schedules (RBI Returns / SLR / CRR feeders / RoC) required? | D8: Limited to certain entity types. | E8: text
A9: Dashboards & BI
A10: 4 | B10: Dashboards & BI | C10: Custom role-based dashboards required? | D10: Adds dashboard composition + access work. | E10: yesno
A11: 5 | B11: Dashboards & BI | C11: Real-time vs. T+1 freshness expectation per dashboard. | D11: Drives data layer (OLTP vs. warehouse). | E11: text
A12: 6 | B12: Dashboards & BI | C12: BI tool of choice (native Crego / Power BI / Tableau / Metabase / Looker)? | D12: Affects data export pipeline. | E12: single
A13: 7 | B13: Dashboards & BI | C13: Scheduled email reports needed? | D13: Adds report scheduler. | E13: yesno
A14: 8 | B14: Dashboards & BI | C14: Data export rights (CSV / API / direct DB / read replica)? | D14: Implications for security. | E14: multi

Sheet 14. Timeline & Go-Live
A1: 14. Timeline & Go-Live
A2: Environments, training, hypercare, post-go-live support.
A4: # | B4: Section | C4: Question | D4: Why it matters / Scoping impact | E4: Response type | F4: Answer | G4: Notes / Follow-up | H4: Owner (Crego) | I4: Priority | J4: Blocker for Go-Live?
A5: Environments & Releases
A6: 1 | B6: Environments & Releases | C6: Environments needed (dev / QA / pre-prod / prod / DR)? | D6: Each environment has cost + setup time. | E6: multi
A7: 2 | B7: Environments & Releases | C7: Pre-prod environment refresh frequency from prod? | D7: Affects support workflow. | E7: single
A8: 3 | B8: Environments & Releases | C8: UAT environment users + duration? | D8: Sets license & support window. | E8: text
A9: 4 | B9: Environments & Releases | C9: Code freeze and cutover window dates? | D9: Anchors release plan. | E9: text
A10: Training & Change
A11: 5 | B11: Training & Change | C11: Training delivery preference (in-person / remote / TTT / e-learning)? | D11: Affects content + travel cost. | E11: single
A12: 6 | B12: Training & Change | C12: Number of users to be trained (by role)? | D12: Sizes training load. | E12: text
A13: 7 | B13: Training & Change | C13: Training material languages? | D13: Localization effort. | E13: text
A14: 8 | B14: Training & Change | C14: Internal change management owner identified? | D14: Adoption risk. | E14: yesno
A15: Hypercare & Support
A16: 9 | B16: Hypercare & Support | C16: Hypercare duration & coverage (24x7 / business hours)? | D16: Cost & rota implications. | E16: text
A17: 10 | B17: Hypercare & Support | C17: Production support model post-hypercare (Crego managed / shared / client)? | D17: Defines run-cost. | E17: single
A18: 11 | B18: Hypercare & Support | C18: Severity definition and SLA expectations (P1/P2/P3/P4)? | D18: Anchors support contract. | E18: text
A19: 12 | B19: Hypercare & Support | C19: Production access policy for Crego support (read-only / break-glass / time-bound)? | D19: Affects support efficiency vs. risk. | E19: single

Sheet 15. Scoping Summary
A1: Scoping Summary — auto-aggregated
A2: Counts update automatically as you fill in answers, priorities, and blocker flags across the workbook.
A4: Sheet | B4: Total Questions | C4: Answered | D4: Blockers (Yes) | E4: Must-Have | F4: Completeness %
A5: 1. Tier 1 — Screener | B5: 30 | C5: =COUNTIFS('1. Tier 1 — Screener'!C5:C40,"<>",'1. Tier 1 — Screener'!F5:F40,"<>") -> 0 | D5: =COUNTIF('1. Tier 1 — Screener'!J5:J40,"Yes") -> 0 | E5: =COUNTIF('1. Tier 1 — Screener'!I5:I40,"Must") -> 0 | F5: =IFERROR(C5/B5,0) -> 0
A6: 2. LOS Deep-Dive | B6: 33 | C6: =COUNTIFS('2. LOS Deep-Dive'!C5:C44,"<>",'2. LOS Deep-Dive'!F5:F44,"<>") -> 0 | D6: =COUNTIF('2. LOS Deep-Dive'!J5:J44,"Yes") -> 0 | E6: =COUNTIF('2. LOS Deep-Dive'!I5:I44,"Must") -> 0 | F6: =IFERROR(C6/B6,0) -> 0
A7: 3. LMS Deep-Dive | B7: 29 | C7: =COUNTIFS('3. LMS Deep-Dive'!C5:C40,"<>",'3. LMS Deep-Dive'!F5:F40,"<>") -> 0 | D7: =COUNTIF('3. LMS Deep-Dive'!J5:J40,"Yes") -> 0 | E7: =COUNTIF('3. LMS Deep-Dive'!I5:I40,"Must") -> 0 | F7: =IFERROR(C7/B7,0) -> 0
A8: 4. SCF Deep-Dive | B8: 20 | C8: =COUNTIFS('4. SCF Deep-Dive'!C5:C29,"<>",'4. SCF Deep-Dive'!F5:F29,"<>") -> 0 | D8: =COUNTIF('4. SCF Deep-Dive'!J5:J29,"Yes") -> 0 | E8: =COUNTIF('4. SCF Deep-Dive'!I5:I29,"Must") -> 0 | F8: =IFERROR(C8/B8,0) -> 0
A9: 5. Term Loan Deep-Dive | B9: 14 | C9: =COUNTIFS('5. Term Loan Deep-Dive'!C5:C22,"<>",'5. Term Loan Deep-Dive'!F5:F22,"<>") -> 0 | D9: =COUNTIF('5. Term Loan Deep-Dive'!J5:J22,"Yes") -> 0 | E9: =COUNTIF('5. Term Loan Deep-Dive'!I5:I22,"Must") -> 0 | F9: =IFERROR(C9/B9,0) -> 0
A10: 6. LOS for SCF & TL | B10: 14 | C10: =COUNTIFS('6. LOS for SCF & TL'!C5:C22,"<>",'6. LOS for SCF & TL'!F5:F22,"<>") -> 0 | D10: =COUNTIF('6. LOS for SCF & TL'!J5:J22,"Yes") -> 0 | E10: =COUNTIF('6. LOS for SCF & TL'!I5:I22,"Must") -> 0 | F10: =IFERROR(C10/B10,0) -> 0
A11: 7. Users, Roles & Access | B11: 13 | C11: =COUNTIFS('7. Users, Roles & Access'!C5:C20,"<>",'7. Users, Roles & Access'!F5:F20,"<>") -> 0 | D11: =COUNTIF('7. Users, Roles & Access'!J5:J20,"Yes") -> 0 | E11: =COUNTIF('7. Users, Roles & Access'!I5:I20,"Must") -> 0 | F11: =IFERROR(C11/B11,0) -> 0
A12: 8. Maker-Checker & Approvals | B12: 9 | C12: =COUNTIFS('8. Maker-Checker & Approvals'!C5:C15,"<>",'8. Maker-Checker & Approvals'!F5:F15,"<>") -> 0 | D12: =COUNTIF('8. Maker-Checker & Approvals'!J5:J15,"Yes") -> 0 | E12: =COUNTIF('8. Maker-Checker & Approvals'!I5:I15,"Must") -> 0 | F12: =IFERROR(C12/B12,0) -> 0
A13: 9. Bulk Operations | B13: 13 | C13: =COUNTIFS('9. Bulk Operations'!C5:C19,"<>",'9. Bulk Operations'!F5:F19,"<>") -> 0 | D13: =COUNTIF('9. Bulk Operations'!J5:J19,"Yes") -> 0 | E13: =COUNTIF('9. Bulk Operations'!I5:I19,"Must") -> 0 | F13: =IFERROR(C13/B13,0) -> 0
A14: 10. APIs & Integrations | B14: 18 | C14: =COUNTIFS('10. APIs & Integrations'!C5:C24,"<>",'10. APIs & Integrations'!F5:F24,"<>") -> 0 | D14: =COUNTIF('10. APIs & Integrations'!J5:J24,"Yes") -> 0 | E14: =COUNTIF('10. APIs & Integrations'!I5:I24,"Must") -> 0 | F14: =IFERROR(C14/B14,0) -> 0
A15: 11. Compliance & Security | B15: 17 | C15: =COUNTIFS('11. Compliance & Security'!C5:C24,"<>",'11. Compliance & Security'!F5:F24,"<>") -> 0 | D15: =COUNTIF('11. Compliance & Security'!J5:J24,"Yes") -> 0 | E15: =COUNTIF('11. Compliance & Security'!I5:I24,"Must") -> 0 | F15: =IFERROR(C15/B15,0) -> 0
A16: 12. Data Migration | B16: 10 | C16: =COUNTIFS('12. Data Migration'!C5:C16,"<>",'12. Data Migration'!F5:F16,"<>") -> 0 | D16: =COUNTIF('12. Data Migration'!J5:J16,"Yes") -> 0 | E16: =COUNTIF('12. Data Migration'!I5:I16,"Must") -> 0 | F16: =IFERROR(C16/B16,0) -> 0
A17: 13. Reporting & Dashboards | B17: 8 | C17: =COUNTIFS('13. Reporting & Dashboards'!C5:C14,"<>",'13. Reporting & Dashboards'!F5:F14,"<>") -> 0 | D17: =COUNTIF('13. Reporting & Dashboards'!J5:J14,"Yes") -> 0 | E17: =COUNTIF('13. Reporting & Dashboards'!I5:I14,"Must") -> 0 | F17: =IFERROR(C17/B17,0) -> 0
A18: 14. Timeline & Go-Live | B18: 12 | C18: =COUNTIFS('14. Timeline & Go-Live'!C5:C19,"<>",'14. Timeline & Go-Live'!F5:F19,"<>") -> 0 | D18: =COUNTIF('14. Timeline & Go-Live'!J5:J19,"Yes") -> 0 | E18: =COUNTIF('14. Timeline & Go-Live'!I5:I19,"Must") -> 0 | F18: =IFERROR(C18/B18,0) -> 0
A19: TOTAL | B19: =SUM(B5:B18) -> 240 | C19: =SUM(C5:C18) -> 0 | D19: =SUM(D5:D18) -> 0 | E19: =SUM(E5:E18) -> 0 | F19: =IFERROR(C19/B19,0) -> 0
A21: Risk readout
A22: If Blockers (Yes) > 0 in any sheet, list them in the engagement risk register before estimating.
A23: If Completeness < 60% on a sheet for a module that's in-scope, schedule a follow-up before sizing the SOW.
A24: Must-Have answers feed directly into the MVP scope; Should / Nice items are negotiable for Phase 2.
A25: Re-run this scoping pass after every major requirement workshop and version the workbook.
